<?xml version="1.0" encoding="UTF-8"?>
<!-- Generated by org.testng.reporters.JUnitReportReporter -->
<testsuite hostname="BM4SW36Y2" name="com.kishan.example.library.service.LibraryServiceImplTest" tests="1" failures="1" timestamp="21 Apr 2020 04:56:07 GMT" time="0.132" errors="0">
  <testcase name="saveLibraryTestCaseThree" time="0.132" classname="com.kishan.example.library.service.LibraryServiceImplTest">
    <failure type="org.testng.TestException" message="
Expected exception java.lang.Exception but got org.testng.TestException: 
Method LibraryServiceImplTest.saveLibraryTestCaseThree()[pri:0, instance:com.kishan.example.library.service.LibraryServiceImplTest@29ca901e] should have thrown an exception of class java.lang.Exception">
      <![CDATA[org.testng.TestException: 
Expected exception java.lang.Exception but got org.testng.TestException: 
Method LibraryServiceImplTest.saveLibraryTestCaseThree()[pri:0, instance:com.kishan.example.library.service.LibraryServiceImplTest@29ca901e] should have thrown an exception of class java.lang.Exception
	at org.testng.internal.Invoker.handleInvocationResults(Invoker.java:1497)
	at org.testng.internal.Invoker.invokeTestMethods(Invoker.java:1245)
	at org.testng.internal.TestMethodWorker.invokeTestMethods(TestMethodWorker.java:127)
	at org.testng.internal.TestMethodWorker.run(TestMethodWorker.java:111)
	at org.testng.TestRunner.privateRun(TestRunner.java:767)
	at org.testng.TestRunner.run(TestRunner.java:617)
	at org.testng.SuiteRunner.runTest(SuiteRunner.java:334)
	at org.testng.SuiteRunner.runSequentially(SuiteRunner.java:329)
	at org.testng.SuiteRunner.privateRun(SuiteRunner.java:291)
	at org.testng.SuiteRunner.run(SuiteRunner.java:240)
	at org.testng.SuiteRunnerWorker.runSuite(SuiteRunnerWorker.java:52)
	at org.testng.SuiteRunnerWorker.run(SuiteRunnerWorker.java:86)
	at org.testng.TestNG.runSuitesSequentially(TestNG.java:1198)
	at org.testng.TestNG.runSuitesLocally(TestNG.java:1123)
	at org.testng.TestNG.run(TestNG.java:1031)
	at org.testng.remote.RemoteTestNG.run(RemoteTestNG.java:115)
	at org.testng.remote.RemoteTestNG.initAndRun(RemoteTestNG.java:207)
	at org.testng.remote.RemoteTestNG.main(RemoteTestNG.java:178)
Caused by: org.testng.TestException: 
Method LibraryServiceImplTest.saveLibraryTestCaseThree()[pri:0, instance:com.kishan.example.library.service.LibraryServiceImplTest@29ca901e] should have thrown an exception of class java.lang.Exception
]]>
    </failure>
  </testcase> <!-- saveLibraryTestCaseThree -->
</testsuite> <!-- com.kishan.example.library.service.LibraryServiceImplTest -->
